Workbook

Sheet Summary
A1: AI ad platforms: quarterly sales analysis
A2: AppLovin, Reddit, Pinterest and Duolingo, Q3 2024 – Q2 2026.
A4: Latest quarter scorecard
A5: Quarter: | B5: Q4 2025 | C5: ← pick any quarter from Q3 2025 onward
A7: Metric | B7: AppLovin | C7: Reddit | D7: Pinterest | E7: Duolingo
A8: Revenue ($M) | B8: =INDEX(Analysis!B$7:B$14,MATCH($B$5,Analysis!$A$7:$A$14,0)) -> 1657.944 | C8: =INDEX(Analysis!C$7:C$14,MATCH($B$5,Analysis!$A$7:$A$14,0)) -> 725.6 | D8: =INDEX(Analysis!D$7:D$14,MATCH($B$5,Analysis!$A$7:$A$14,0)) -> 1319.347 | E8: =INDEX(Analysis!E$7:E$14,MATCH($B$5,Analysis!$A$7:$A$14,0)) -> 282.868
A9: Revenue YoY | B9: =INDEX(Analysis!B$7:B$14,MATCH($B$5,Analysis!$A$7:$A$14,0))/INDEX(Analysis!B$7:B$14,MATCH($B$5,Analysis!$A$7:$A$14,0)-4)-1 -> 0.65879496 | C9: =INDEX(Analysis!C$7:C$14,MATCH($B$5,Analysis!$A$7:$A$14,0))/INDEX(Analysis!C$7:C$14,MATCH($B$5,Analysis!$A$7:$A$14,0)-4)-1 -> 0.69651625 | D9: =INDEX(Analysis!D$7:D$14,MATCH($B$5,Analysis!$A$7:$A$14,0))/INDEX(Analysis!D$7:D$14,MATCH($B$5,Analysis!$A$7:$A$14,0)-4)-1 -> 0.14315285 | E9: =INDEX(Analysis!E$7:E$14,MATCH($B$5,Analysis!$A$7:$A$14,0))/INDEX(Analysis!E$7:E$14,MATCH($B$5,Analysis!$A$7:$A$14,0)-4)-1 -> 0.34988308
A10: Revenue QoQ | B10: =INDEX(Analysis!B$7:B$14,MATCH($B$5,Analysis!$A$7:$A$14,0))/INDEX(Analysis!B$7:B$14,MATCH($B$5,Analysis!$A$7:$A$14,0)-1)-1 -> 0.17999352 | C10: =INDEX(Analysis!C$7:C$14,MATCH($B$5,Analysis!$A$7:$A$14,0))/INDEX(Analysis!C$7:C$14,MATCH($B$5,Analysis!$A$7:$A$14,0)-1)-1 -> 0.24053061 | D10: =INDEX(Analysis!D$7:D$14,MATCH($B$5,Analysis!$A$7:$A$14,0))/INDEX(Analysis!D$7:D$14,MATCH($B$5,Analysis!$A$7:$A$14,0)-1)-1 -> 0.25747304 | E10: =INDEX(Analysis!E$7:E$14,MATCH($B$5,Analysis!$A$7:$A$14,0))/INDEX(Analysis!E$7:E$14,MATCH($B$5,Analysis!$A$7:$A$14,0)-1)-1 -> 0.041054348
A11: Adj. EBITDA margin | B11: =INDEX(Analysis!B$30:B$37,MATCH($B$5,Analysis!$A$30:$A$37,0)) -> 0.84362258 | C11: =INDEX(Analysis!C$30:C$37,MATCH($B$5,Analysis!$A$30:$A$37,0)) -> 0.45066152 | D11: =INDEX(Analysis!D$30:D$37,MATCH($B$5,Analysis!$A$30:$A$37,0)) -> 0.41043031 | E11: =INDEX(Analysis!E$30:E$37,MATCH($B$5,Analysis!$A$30:$A$37,0)) -> 0.29818855
A12: Trailing 4Q revenue ($M) | B12: =SUM(OFFSET(Analysis!B$7,MATCH($B$5,Analysis!$A$7:$A$14,0)-4,0,4,1)) -> 5480.717 | C12: =SUM(OFFSET(Analysis!C$7,MATCH($B$5,Analysis!$A$7:$A$14,0)-4,0,4,1)) -> 2202.499 | D12: =SUM(OFFSET(Analysis!D$7,MATCH($B$5,Analysis!$A$7:$A$14,0)-4,0,4,1)) -> 4221.767 | E12: =SUM(OFFSET(Analysis!E$7,MATCH($B$5,Analysis!$A$7:$A$14,0)-4,0,4,1)) -> 1037.589
A13: Revenue share of group | B13: =B8/SUM($B$8:$E$8) -> 0.41596695 | C13: =C8/SUM($B$8:$E$8) -> 0.18204814 | D13: =D8/SUM($B$8:$E$8) -> 0.33101525 | E13: =E8/SUM($B$8:$E$8) -> 0.07096967
A15: What the numbers say
A16: ="Fastest grower: "&INDEX($B$7:$E$7,MATCH(MAX($B$9:$E$9),$B$9:$E$9,0))&" at "&TEXT(MAX($B$9:$E$9),"0%")&" YoY revenue growth in "&$B$5&"." -> Fastest grower: Reddit at 70% YoY revenue growth in Q4 2025.
A17: ="Most profitable: "&INDEX($B$7:$E$7,MATCH(MAX($B$11:$E$11),$B$11:$E$11,0))&", converting "&TEXT(MAX($B$11:$E$11),"0%")&" of revenue to adj. EBITDA." -> Most profitable: AppLovin, converting 84% of revenue to adj. EBITDA.
A18: ="Monetization: Reddit revenue grew "&TEXT(Analysis!B56,"0%")&" vs "&TEXT(Analysis!C56,"0%")&" user growth in Q2 2026, a "&TEXT(Analysis!D56*100,"0")&"-point gap. ARPU, not audience, is driving sales." -> Monetization: Reddit revenue grew 61% vs 18% user growth in Q2 2026, a 43-point gap. ARPU, not audience, is driving sales.
A19: ="Outlook: guidance midpoints imply Q3 2026 YoY growth of "&TEXT(Analysis!K56,"0%")&" (AppLovin), "&TEXT(Analysis!K57,"0%")&" (Reddit), "&TEXT(Analysis!K58,"0%")&" (Pinterest) and "&TEXT(Analysis!K59,"0%")&" (Duolingo)." -> Outlook: guidance midpoints imply Q3 2026 YoY growth of 47% (AppLovin), 48% (Reddit), 14% (Pinterest) and 11% (Duolingo).

Sheet Raw Data
A1: Raw quarterly data
A2: Reported figures, $ millions unless noted. Blue = hardcoded from company filings (see Sources tab). AppLovin is continuing operations (apps business divested in 2025).
A4: Company | B4: Ticker | C4: Quarter | D4: Period end | E4: Q index | F4: Revenue ($M) | G4: Adj. EBITDA ($M) | H4: User metric | I4: Users (M) | J4: ARPU ($) | K4: Source key
A5: AppLovin | B5: APP | C5: Q3 2024 | D5: 2024-09-30 | E5: 1 | F5: 835.186 | G5: 647.017 | H5: n/a | K5: APP-3Q25
A6: AppLovin | B6: APP | C6: Q4 2024 | D6: 2024-12-31 | E6: 2 | F6: 999.487 | G6: 769.832 | H6: n/a | K6: APP-4Q25
A7: AppLovin | B7: APP | C7: Q1 2025 | D7: 2025-03-31 | E7: 3 | F7: 1158.974 | G7: 937.772 | H7: n/a | K7: APP-1Q26
A8: AppLovin | B8: APP | C8: Q2 2025 | D8: 2025-06-30 | E8: 4 | F8: 1258.754 | G8: 1018.347 | H8: n/a | K8: APP-2Q26
A9: AppLovin | B9: APP | C9: Q3 2025 | D9: 2025-09-30 | E9: 5 | F9: 1405.045 | G9: 1157.654 | H9: n/a | K9: APP-3Q25
A10: AppLovin | B10: APP | C10: Q4 2025 | D10: 2025-12-31 | E10: 6 | F10: 1657.944 | G10: 1398.679 | H10: n/a | K10: APP-4Q25
A11: AppLovin | B11: APP | C11: Q1 2026 | D11: 2026-03-31 | E11: 7 | F11: 1842.449 | G11: 1556.919 | H11: n/a | K11: APP-1Q26
A12: AppLovin | B12: APP | C12: Q2 2026 | D12: 2026-06-30 | E12: 8 | F12: 1923.686 | G12: 1613.823 | H12: n/a | K12: APP-2Q26
A13: Reddit | B13: RDDT | C13: Q3 2024 | D13: 2024-09-30 | E13: 1 | F13: 348.351 | G13: 94.149 | H13: DAUq | I13: 97.2 | J13: 3.58 | K13: RDDT-3Q25
A14: Reddit | B14: RDDT | C14: Q4 2024 | D14: 2024-12-31 | E14: 2 | F14: 427.7 | G14: 154.3 | H14: DAUq | I14: 101.7 | J14: 4.21 | K14: RDDT-4Q25
A15: Reddit | B15: RDDT | C15: Q1 2025 | D15: 2025-03-31 | E15: 3 | F15: 392.361 | G15: 115.271 | H15: DAUq | I15: 108.1 | J15: 3.63 | K15: RDDT-1Q26
A16: Reddit | B16: RDDT | C16: Q2 2025 | D16: 2025-06-30 | E16: 4 | F16: 499.627 | G16: 166.749 | H16: DAUq | I16: 110.4 | J16: 4.53 | K16: RDDT-2Q26
A17: Reddit | B17: RDDT | C17: Q3 2025 | D17: 2025-09-30 | E17: 5 | F17: 584.911 | G17: 236.007 | H17: DAUq | I17: 116 | J17: 5.04 | K17: RDDT-3Q25
A18: Reddit | B18: RDDT | C18: Q4 2025 | D18: 2025-12-31 | E18: 6 | F18: 725.6 | G18: 327 | H18: DAUq | I18: 121.4 | J18: 5.98 | K18: RDDT-4Q25
A19: Reddit | B19: RDDT | C19: Q1 2026 | D19: 2026-03-31 | E19: 7 | F19: 663.411 | G19: 265.97 | H19: DAUq | I19: 126.8 | J19: 5.23 | K19: RDDT-1Q26
A20: Reddit | B20: RDDT | C20: Q2 2026 | D20: 2026-06-30 | E20: 8 | F20: 804.905 | G20: 342.81 | H20: DAUq | I20: 130.3 | J20: 6.18 | K20: RDDT-2Q26
A21: Pinterest | B21: PINS | C21: Q3 2024 | D21: 2024-09-30 | E21: 1 | F21: 898.373 | G21: 246.99 | H21: MAUs | I21: 537 | J21: 1.7 | K21: PINS-3Q25
A22: Pinterest | B22: PINS | C22: Q4 2024 | D22: 2024-12-31 | E22: 2 | F22: 1154.13 | G22: 470.943 | H22: MAUs | I22: 553 | J22: 2.12 | K22: PINS-4Q25
A23: Pinterest | B23: PINS | C23: Q1 2025 | D23: 2025-03-31 | E23: 3 | F23: 854.988 | G23: 171.649 | H23: MAUs | I23: 570 | J23: 1.52 | K23: PINS-1Q26
A24: Pinterest | B24: PINS | C24: Q2 2025 | D24: 2025-06-30 | E24: 4 | F24: 998.227 | G24: 250.776 | H24: MAUs | I24: 578 | J24: 1.74 | K24: PINS-2Q26
... A28: Pinterest | B28: PINS | C28: Q2 2026 | D28: 2026-06-30 | E28: 8 | F28: 1179.654 | G28: 311.307 | H28: MAUs | I28: 640 | J28: 1.86 | K28: PINS-2Q26
A29: Duolingo | B29: DUOL | C29: Q3 2024 | D29: 2024-09-30 | E29: 1 | F29: 192.594 | G29: 47.508 | H29: DAUs | I29: 37.2 | K29: DUOL-3Q25
A30: Duolingo | B30: DUOL | C30: Q4 2024 | D30: 2024-12-31 | E30: 2 | F30: 209.55 | G30: 52.312 | H30: DAUs | I30: 40.5 | K30: DUOL-4Q25
A31: Duolingo | B31: DUOL | C31: Q1 2025 | D31: 2025-03-31 | E31: 3 | F31: 230.743 | G31: 62.804 | H31: DAUs | I31: 46.6 | K31: DUOL-1Q26
A32: Duolingo | B32: DUOL | C32: Q2 2025 | D32: 2025-06-30 | E32: 4 | F32: 252.265 | G32: 78.68 | H32: DAUs | I32: 47.7 | K32: DUOL-2Q26
A33: Duolingo | B33: DUOL | C33: Q3 2025 | D33: 2025-09-30 | E33: 5 | F33: 271.713 | G33: 80.046 | H33: DAUs | I33: 50.5 | K33: DUOL-3Q25
A34: Duolingo | B34: DUOL | C34: Q4 2025 | D34: 2025-12-31 | E34: 6 | F34: 282.868 | G34: 84.348 | H34: DAUs | I34: 52.7 | K34: DUOL-4Q25
A35: Duolingo | B35: DUOL | C35: Q1 2026 | D35: 2026-03-31 | E35: 7 | F35: 291.967 | G35: 83.432 | H35: DAUs | I35: 56.5 | K35: DUOL-1Q26
A36: Duolingo | B36: DUOL | C36: Q2 2026 | D36: 2026-06-30 | E36: 8 | F36: 298.454 | G36: 77.315 | H36: DAUs | I36: 58.7 | K36: DUOL-2Q26
A38: Notes
A39: Reddit Q4 2024 and Q4 2025 revenue/EBITDA are reported to $0.1M; all other figures are exact to $1K.
A40: Duolingo Q3 2025 net income included a one-time $222.7M tax benefit; EBITDA is unaffected, so this book uses Adj. EBITDA.
A41: AppLovin does not report user metrics. Reddit = daily active uniques, Pinterest = monthly active users, Duolingo = daily active users.

Sheet Analysis
A1: Sales analysis
A2: Every figure on this tab is a formula on the Raw Data table (SUMIFS lookups, growth math, margins). Change a raw value and everything downstream updates.
A4: Quarterly revenue ($M) | G4: Adj. EBITDA ($M)
A6: Quarter | B6: AppLovin | C6: Reddit | D6: Pinterest | E6: Duolingo | G6: Quarter | H6: AppLovin | I6: Reddit | J6: Pinterest | K6: Duolingo
A7: Q3 2024 | B7: =SUMIFS('Raw Data'!$F$5:$F$36,'Raw Data'!$B$5:$B$36,"APP",'Raw Data'!$C$5:$C$36,$A7) -> 835.186 | C7: =SUMIFS('Raw Data'!$F$5:$F$36,'Raw Data'!$B$5:$B$36,"RDDT",'Raw Data'!$C$5:$C$36,$A7) -> 348.351 | D7: =SUMIFS('Raw Data'!$F$5:$F$36,'Raw Data'!$B$5:$B$36,"PINS",'Raw Data'!$C$5:$C$36,$A7) -> 898.373 | E7: =SUMIFS('Raw Data'!$F$5:$F$36,'Raw Data'!$B$5:$B$36,"DUOL",'Raw Data'!$C$5:$C$36,$A7) -> 192.594 | G7: Q3 2024 | H7: =SUMIFS('Raw Data'!$G$5:$G$36,'Raw Data'!$B$5:$B$36,"APP",'Raw Data'!$C$5:$C$36,$G7) -> 647.017 | I7: =SUMIFS('Raw Data'!$G$5:$G$36,'Raw Data'!$B$5:$B$36,"RDDT",'Raw Data'!$C$5:$C$36,$G7) -> 94.149 | J7: =SUMIFS('Raw Data'!$G$5:$G$36,'Raw Data'!$B$5:$B$36,"PINS",'Raw Data'!$C$5:$C$36,$G7) -> 246.99 | K7: =SUMIFS('Raw Data'!$G$5:$G$36,'Raw Data'!$B$5:$B$36,"DUOL",'Raw Data'!$C$5:$C$36,$G7) -> 47.508
A8: Q4 2024 | B8: =SUMIFS('Raw Data'!$F$5:$F$36,'Raw Data'!$B$5:$B$36,"APP",'Raw Data'!$C$5:$C$36,$A8) -> 999.487 | C8: =SUMIFS('Raw Data'!$F$5:$F$36,'Raw Data'!$B$5:$B$36,"RDDT",'Raw Data'!$C$5:$C$36,$A8) -> 427.7 | D8: =SUMIFS('Raw Data'!$F$5:$F$36,'Raw Data'!$B$5:$B$36,"PINS",'Raw Data'!$C$5:$C$36,$A8) -> 1154.13 | E8: =SUMIFS('Raw Data'!$F$5:$F$36,'Raw Data'!$B$5:$B$36,"DUOL",'Raw Data'!$C$5:$C$36,$A8) -> 209.55 | G8: Q4 2024 | H8: =SUMIFS('Raw Data'!$G$5:$G$36,'Raw Data'!$B$5:$B$36,"APP",'Raw Data'!$C$5:$C$36,$G8) -> 769.832 | I8: =SUMIFS('Raw Data'!$G$5:$G$36,'Raw Data'!$B$5:$B$36,"RDDT",'Raw Data'!$C$5:$C$36,$G8) -> 154.3 | J8: =SUMIFS('Raw Data'!$G$5:$G$36,'Raw Data'!$B$5:$B$36,"PINS",'Raw Data'!$C$5:$C$36,$G8) -> 470.943 | K8: =SUMIFS('Raw Data'!$G$5:$G$36,'Raw Data'!$B$5:$B$36,"DUOL",'Raw Data'!$C$5:$C$36,$G8) -> 52.312
A9: Q1 2025 | B9: =SUMIFS('Raw Data'!$F$5:$F$36,'Raw Data'!$B$5:$B$36,"APP",'Raw Data'!$C$5:$C$36,$A9) -> 1158.974 | C9: =SUMIFS('Raw Data'!$F$5:$F$36,'Raw Data'!$B$5:$B$36,"RDDT",'Raw Data'!$C$5:$C$36,$A9) -> 392.361 | D9: =SUMIFS('Raw Data'!$F$5:$F$36,'Raw Data'!$B$5:$B$36,"PINS",'Raw Data'!$C$5:$C$36,$A9) -> 854.988 | E9: =SUMIFS('Raw Data'!$F$5:$F$36,'Raw Data'!$B$5:$B$36,"DUOL",'Raw Data'!$C$5:$C$36,$A9) -> 230.743 | G9: Q1 2025 | H9: =SUMIFS('Raw Data'!$G$5:$G$36,'Raw Data'!$B$5:$B$36,"APP",'Raw Data'!$C$5:$C$36,$G9) -> 937.772 | I9: =SUMIFS('Raw Data'!$G$5:$G$36,'Raw Data'!$B$5:$B$36,"RDDT",'Raw Data'!$C$5:$C$36,$G9) -> 115.271 | J9: =SUMIFS('Raw Data'!$G$5:$G$36,'Raw Data'!$B$5:$B$36,"PINS",'Raw Data'!$C$5:$C$36,$G9) -> 171.649 | K9: =SUMIFS('Raw Data'!$G$5:$G$36,'Raw Data'!$B$5:$B$36,"DUOL",'Raw Data'!$C$5:$C$36,$G9) -> 62.804
A10: Q2 2025 | B10: =SUMIFS('Raw Data'!$F$5:$F$36,'Raw Data'!$B$5:$B$36,"APP",'Raw Data'!$C$5:$C$36,$A10) -> 1258.754 | C10: =SUMIFS('Raw Data'!$F$5:$F$36,'Raw Data'!$B$5:$B$36,"RDDT",'Raw Data'!$C$5:$C$36,$A10) -> 499.627 | D10: =SUMIFS('Raw Data'!$F$5:$F$36,'Raw Data'!$B$5:$B$36,"PINS",'Raw Data'!$C$5:$C$36,$A10) -> 998.227 | E10: =SUMIFS('Raw Data'!$F$5:$F$36,'Raw Data'!$B$5:$B$36,"DUOL",'Raw Data'!$C$5:$C$36,$A10) -> 252.265 | G10: Q2 2025 | H10: =SUMIFS('Raw Data'!$G$5:$G$36,'Raw Data'!$B$5:$B$36,"APP",'Raw Data'!$C$5:$C$36,$G10) -> 1018.347 | I10: =SUMIFS('Raw Data'!$G$5:$G$36,'Raw Data'!$B$5:$B$36,"RDDT",'Raw Data'!$C$5:$C$36,$G10) -> 166.749 | J10: =SUMIFS('Raw Data'!$G$5:$G$36,'Raw Data'!$B$5:$B$36,"PINS",'Raw Data'!$C$5:$C$36,$G10) -> 250.776 | K10: =SUMIFS('Raw Data'!$G$5:$G$36,'Raw Data'!$B$5:$B$36,"DUOL",'Raw Data'!$C$5:$C$36,$G10) -> 78.68
A11: Q3 2025 | B11: =SUMIFS('Raw Data'!$F$5:$F$36,'Raw Data'!$B$5:$B$36,"APP",'Raw Data'!$C$5:$C$36,$A11) -> 1405.045 | C11: =SUMIFS('Raw Data'!$F$5:$F$36,'Raw Data'!$B$5:$B$36,"RDDT",'Raw Data'!$C$5:$C$36,$A11) -> 584.911 | D11: =SUMIFS('Raw Data'!$F$5:$F$36,'Raw Data'!$B$5:$B$36,"PINS",'Raw Data'!$C$5:$C$36,$A11) -> 1049.205 | E11: =SUMIFS('Raw Data'!$F$5:$F$36,'Raw Data'!$B$5:$B$36,"DUOL",'Raw Data'!$C$5:$C$36,$A11) -> 271.713 | G11: Q3 2025 | H11: =SUMIFS('Raw Data'!$G$5:$G$36,'Raw Data'!$B$5:$B$36,"APP",'Raw Data'!$C$5:$C$36,$G11) -> 1157.654 | I11: =SUMIFS('Raw Data'!$G$5:$G$36,'Raw Data'!$B$5:$B$36,"RDDT",'Raw Data'!$C$5:$C$36,$G11) -> 236.007 | J11: =SUMIFS('Raw Data'!$G$5:$G$36,'Raw Data'!$B$5:$B$36,"PINS",'Raw Data'!$C$5:$C$36,$G11) -> 306.051 | K11: =SUMIFS('Raw Data'!$G$5:$G$36,'Raw Data'!$B$5:$B$36,"DUOL",'Raw Data'!$C$5:$C$36,$G11) -> 80.046
A12: Q4 2025 | B12: =SUMIFS('Raw Data'!$F$5:$F$36,'Raw Data'!$B$5:$B$36,"APP",'Raw Data'!$C$5:$C$36,$A12) -> 1657.944 | C12: =SUMIFS('Raw Data'!$F$5:$F$36,'Raw Data'!$B$5:$B$36,"RDDT",'Raw Data'!$C$5:$C$36,$A12) -> 725.6 | D12: =SUMIFS('Raw Data'!$F$5:$F$36,'Raw Data'!$B$5:$B$36,"PINS",'Raw Data'!$C$5:$C$36,$A12) -> 1319.347 | E12: =SUMIFS('Raw Data'!$F$5:$F$36,'Raw Data'!$B$5:$B$36,"DUOL",'Raw Data'!$C$5:$C$36,$A12) -> 282.868 | G12: Q4 2025 | H12: =SUMIFS('Raw Data'!$G$5:$G$36,'Raw Data'!$B$5:$B$36,"APP",'Raw Data'!$C$5:$C$36,$G12) -> 1398.679 | I12: =SUMIFS('Raw Data'!$G$5:$G$36,'Raw Data'!$B$5:$B$36,"RDDT",'Raw Data'!$C$5:$C$36,$G12) -> 327 | J12: =SUMIFS('Raw Data'!$G$5:$G$36,'Raw Data'!$B$5:$B$36,"PINS",'Raw Data'!$C$5:$C$36,$G12) -> 541.5 | K12: =SUMIFS('Raw Data'!$G$5:$G$36,'Raw Data'!$B$5:$B$36,"DUOL",'Raw Data'!$C$5:$C$36,$G12) -> 84.348
A13: Q1 2026 | B13: =SUMIFS('Raw Data'!$F$5:$F$36,'Raw Data'!$B$5:$B$36,"APP",'Raw Data'!$C$5:$C$36,$A13) -> 1842.449 | C13: =SUMIFS('Raw Data'!$F$5:$F$36,'Raw Data'!$B$5:$B$36,"RDDT",'Raw Data'!$C$5:$C$36,$A13) -> 663.411 | D13: =SUMIFS('Raw Data'!$F$5:$F$36,'Raw Data'!$B$5:$B$36,"PINS",'Raw Data'!$C$5:$C$36,$A13) -> 1007.514 | E13: =SUMIFS('Raw Data'!$F$5:$F$36,'Raw Data'!$B$5:$B$36,"DUOL",'Raw Data'!$C$5:$C$36,$A13) -> 291.967 | G13: Q1 2026 | H13: =SUMIFS('Raw Data'!$G$5:$G$36,'Raw Data'!$B$5:$B$36,"APP",'Raw Data'!$C$5:$C$36,$G13) -> 1556.919 | I13: =SUMIFS('Raw Data'!$G$5:$G$36,'Raw Data'!$B$5:$B$36,"RDDT",'Raw Data'!$C$5:$C$36,$G13) -> 265.97 | J13: =SUMIFS('Raw Data'!$G$5:$G$36,'Raw Data'!$B$5:$B$36,"PINS",'Raw Data'!$C$5:$C$36,$G13) -> 206.51 | K13: =SUMIFS('Raw Data'!$G$5:$G$36,'Raw Data'!$B$5:$B$36,"DUOL",'Raw Data'!$C$5:$C$36,$G13) -> 83.432
A14: Q2 2026 | B14: =SUMIFS('Raw Data'!$F$5:$F$36,'Raw Data'!$B$5:$B$36,"APP",'Raw Data'!$C$5:$C$36,$A14) -> 1923.686 | C14: =SUMIFS('Raw Data'!$F$5:$F$36,'Raw Data'!$B$5:$B$36,"RDDT",'Raw Data'!$C$5:$C$36,$A14) -> 804.905 | D14: =SUMIFS('Raw Data'!$F$5:$F$36,'Raw Data'!$B$5:$B$36,"PINS",'Raw Data'!$C$5:$C$36,$A14) -> 1179.654 | E14: =SUMIFS('Raw Data'!$F$5:$F$36,'Raw Data'!$B$5:$B$36,"DUOL",'Raw Data'!$C$5:$C$36,$A14) -> 298.454 | G14: Q2 2026 | H14: =SUMIFS('Raw Data'!$G$5:$G$36,'Raw Data'!$B$5:$B$36,"APP",'Raw Data'!$C$5:$C$36,$G14) -> 1613.823 | I14: =SUMIFS('Raw Data'!$G$5:$G$36,'Raw Data'!$B$5:$B$36,"RDDT",'Raw Data'!$C$5:$C$36,$G14) -> 342.81 | J14: =SUMIFS('Raw Data'!$G$5:$G$36,'Raw Data'!$B$5:$B$36,"PINS",'Raw Data'!$C$5:$C$36,$G14) -> 311.307 | K14: =SUMIFS('Raw Data'!$G$5:$G$36,'Raw Data'!$B$5:$B$36,"DUOL",'Raw Data'!$C$5:$C$36,$G14) -> 77.315
A16: Revenue growth, quarter over quarter | G16: Revenue growth, year over year
A17: Q4 is the seasonal peak for ad budgets; watch the Q1 step-down. | G17: Comparable quarter one year earlier.
A18: Quarter | B18: AppLovin | C18: Reddit | D18: Pinterest | E18: Duolingo | G18: Quarter | H18: AppLovin | I18: Reddit | J18: Pinterest | K18: Duolingo
A19: Q4 2024 | B19: =IFERROR(B7/B6-1,"") | C19: =IFERROR(C7/C6-1,"") | D19: =IFERROR(D7/D6-1,"") | E19: =IFERROR(E7/E6-1,"") | G19: Q3 2025 | H19: =IFERROR(B11/B7-1,"") -> 0.68231388 | I19: =IFERROR(C11/C7-1,"") -> 0.67908518 | J19: =IFERROR(D11/D7-1,"") -> 0.16789463 | K19: =IFERROR(E11/E7-1,"") -> 0.41080719
A20: Q1 2025 | B20: =IFERROR(B8/B7-1,"") -> 0.19672384 | C20: =IFERROR(C8/C7-1,"") -> 0.22778462 | D20: =IFERROR(D8/D7-1,"") -> 0.2846891 | E20: =IFERROR(E8/E7-1,"") -> 0.088040126 | G20: Q4 2025 | H20: =IFERROR(B12/B8-1,"") -> 0.65879496 | I20: =IFERROR(C12/C8-1,"") -> 0.69651625 | J20: =IFERROR(D12/D8-1,"") -> 0.14315285 | K20: =IFERROR(E12/E8-1,"") -> 0.34988308
A21: Q2 2025 | B21: =IFERROR(B9/B8-1,"") -> 0.15956886 | C21: =IFERROR(C9/C8-1,"") -> -0.082625672 | D21: =IFERROR(D9/D8-1,"") -> -0.25919264 | E21: =IFERROR(E9/E8-1,"") -> 0.10113577 | G21: Q1 2026 | H21: =IFERROR(B13/B9-1,"") -> 0.58972419 | I21: =IFERROR(C13/C9-1,"") -> 0.69081789 | J21: =IFERROR(D13/D9-1,"") -> 0.17839549 | K21: =IFERROR(E13/E9-1,"") -> 0.26533416
A22: Q3 2025 | B22: =IFERROR(B10/B9-1,"") -> 0.086093389 | C22: =IFERROR(C10/C9-1,"") -> 0.27338599 | D22: =IFERROR(D10/D9-1,"") -> 0.16753335 | E22: =IFERROR(E10/E9-1,"") -> 0.093272602 | G22: Q2 2026 | H22: =IFERROR(B14/B10-1,"") -> 0.52824619 | I22: =IFERROR(C14/C10-1,"") -> 0.61101181 | J22: =IFERROR(D14/D10-1,"") -> 0.18174924 | K22: =IFERROR(E14/E10-1,"") -> 0.18309714
A23: Q4 2025 | B23: =IFERROR(B11/B10-1,"") -> 0.1162189 | C23: =IFERROR(C11/C10-1,"") -> 0.17069534 | D23: =IFERROR(D11/D10-1,"") -> 0.051068545 | E23: =IFERROR(E11/E10-1,"") -> 0.077093533
A24: Q1 2026 | B24: =IFERROR(B12/B11-1,"") -> 0.17999352 | C24: =IFERROR(C12/C11-1,"") -> 0.24053061 | D24: =IFERROR(D12/D11-1,"") -> 0.25747304 | E24: =IFERROR(E12/E11-1,"") -> 0.041054348
A25: Q2 2026 | B25: =IFERROR(B13/B12-1,"") -> 0.11128542 | C25: =IFERROR(C13/C12-1,"") -> -0.085707001 | D25: =IFERROR(D13/D12-1,"") -> -0.23635404 | E25: =IFERROR(E13/E12-1,"") -> 0.032166947
A27: Adj. EBITDA margin | G27: Revenue indexed (Q3 2024 = 100)
A28: Adj. EBITDA ÷ revenue. Operating leverage shows as margin rising with scale. | G28: Puts a $2B and a $0.3B business on one scale.
A29: Quarter | B29: AppLovin | C29: Reddit | D29: Pinterest | E29: Duolingo | G29: Quarter | H29: AppLovin | I29: Reddit | J29: Pinterest | K29: Duolingo
A30: Q3 2024 | B30: =IFERROR(H7/B7,"") -> 0.77469809 | C30: =IFERROR(I7/C7,"") -> 0.2702705 | D30: =IFERROR(J7/D7,"") -> 0.27493035 | E30: =IFERROR(K7/E7,"") -> 0.24667435 | G30: Q3 2024 | H30: =IFERROR(B7/B$7*100,"") -> 100 | I30: =IFERROR(C7/C$7*100,"") -> 100 | J30: =IFERROR(D7/D$7*100,"") -> 100 | K30: =IFERROR(E7/E$7*100,"") -> 100
A31: Q4 2024 | B31: =IFERROR(H8/B8,"") -> 0.77022713 | C31: =IFERROR(I8/C8,"") -> 0.36076689 | D31: =IFERROR(J8/D8,"") -> 0.40805022 | E31: =IFERROR(K8/E8,"") -> 0.2496397 | G31: Q4 2024 | H31: =IFERROR(B8/B$7*100,"") -> 119.67238 | I31: =IFERROR(C8/C$7*100,"") -> 122.77846 | J31: =IFERROR(D8/D$7*100,"") -> 128.46891 | K31: =IFERROR(E8/E$7*100,"") -> 108.80401
A32: Q1 2025 | B32: =IFERROR(H9/B9,"") -> 0.80913981 | C32: =IFERROR(I9/C9,"") -> 0.29378812 | D32: =IFERROR(J9/D9,"") -> 0.20076188 | E32: =IFERROR(K9/E9,"") -> 0.2721816 | G32: Q1 2025 | H32: =IFERROR(B9/B$7*100,"") -> 138.76837 | I32: =IFERROR(C9/C$7*100,"") -> 112.63381 | J32: =IFERROR(D9/D$7*100,"") -> 95.170714 | K32: =IFERROR(E9/E$7*100,"") -> 119.80799
A33: Q2 2025 | B33: =IFERROR(H10/B10,"") -> 0.80901193 | C33: =IFERROR(I10/C10,"") -> 0.33374698 | D33: =IFERROR(J10/D10,"") -> 0.25122142 | E33: =IFERROR(K10/E10,"") -> 0.31189424 | G33: Q2 2025 | H33: =IFERROR(B10/B$7*100,"") -> 150.71541 | I33: =IFERROR(C10/C$7*100,"") -> 143.42631 | J33: =IFERROR(D10/D$7*100,"") -> 111.11498 | K33: =IFERROR(E10/E$7*100,"") -> 130.98279
A34: Q3 2025 | B34: =IFERROR(H11/B11,"") -> 0.82392664 | C34: =IFERROR(I11/C11,"") -> 0.40349216 | D34: =IFERROR(J11/D11,"") -> 0.291698 | E34: =IFERROR(K11/E11,"") -> 0.29459761 | G34: Q3 2025 | H34: =IFERROR(B11/B$7*100,"") -> 168.23139 | I34: =IFERROR(C11/C$7*100,"") -> 167.90852 | J34: =IFERROR(D11/D$7*100,"") -> 116.78946 | K34: =IFERROR(E11/E$7*100,"") -> 141.08072
A35: Q4 2025 | B35: =IFERROR(H12/B12,"") -> 0.84362258 | C35: =IFERROR(I12/C12,"") -> 0.45066152 | D35: =IFERROR(J12/D12,"") -> 0.41043031 | E35: =IFERROR(K12/E12,"") -> 0.29818855 | G35: Q4 2025 | H35: =IFERROR(B12/B$7*100,"") -> 198.51195 | I35: =IFERROR(C12/C$7*100,"") -> 208.29566 | J35: =IFERROR(D12/D$7*100,"") -> 146.8596 | K35: =IFERROR(E12/E$7*100,"") -> 146.8727
A36: Q1 2026 | B36: =IFERROR(H13/B13,"") -> 0.84502692 | C36: =IFERROR(I13/C13,"") -> 0.40091286 | D36: =IFERROR(J13/D13,"") -> 0.20496986 | E36: =IFERROR(K13/E13,"") -> 0.28575832 | G36: Q1 2026 | H36: =IFERROR(B13/B$7*100,"") -> 220.60343 | I36: =IFERROR(C13/C$7*100,"") -> 190.44326 | J36: =IFERROR(D13/D$7*100,"") -> 112.14874 | K36: =IFERROR(E13/E$7*100,"") -> 151.59714
A37: Q2 2026 | B37: =IFERROR(H14/B14,"") -> 0.83892226 | C37: =IFERROR(I14/C14,"") -> 0.42590119 | D37: =IFERROR(J14/D14,"") -> 0.26389687 | E37: =IFERROR(K14/E14,"") -> 0.25905165 | G37: Q2 2026 | H37: =IFERROR(B14/B$7*100,"") -> 230.33025 | I37: =IFERROR(C14/C$7*100,"") -> 231.06149 | J37: =IFERROR(D14/D$7*100,"") -> 131.31005 | K37: =IFERROR(E14/E$7*100,"") -> 154.96537
A40: Users and monetization
A41: Revenue per user = quarterly revenue ÷ reported users. AppLovin reports no user metric.
A42: Quarter | B42: Reddit DAUq (M) | C42: Pinterest MAUs (M) | D42: Duolingo DAUs (M) | E42: Reddit rev / DAUq ($) | G42: Pinterest rev / MAU ($) | H42: Duolingo rev / DAU ($)
A43: Q3 2024 | B43: =SUMIFS('Raw Data'!$I$5:$I$36,'Raw Data'!$B$5:$B$36,"RDDT",'Raw Data'!$C$5:$C$36,$A43) -> 97.2 | C43: =SUMIFS('Raw Data'!$I$5:$I$36,'Raw Data'!$B$5:$B$36,"PINS",'Raw Data'!$C$5:$C$36,$A43) -> 537 | D43: =SUMIFS('Raw Data'!$I$5:$I$36,'Raw Data'!$B$5:$B$36,"DUOL",'Raw Data'!$C$5:$C$36,$A43) -> 37.2 | E43: =IFERROR(C7/B43,"") -> 3.583858 | G43: =IFERROR(D7/C43,"") -> 1.6729479 | H43: =IFERROR(E7/D43,"") -> 5.1772581
A44: Q4 2024 | B44: =SUMIFS('Raw Data'!$I$5:$I$36,'Raw Data'!$B$5:$B$36,"RDDT",'Raw Data'!$C$5:$C$36,$A44) -> 101.7 | C44: =SUMIFS('Raw Data'!$I$5:$I$36,'Raw Data'!$B$5:$B$36,"PINS",'Raw Data'!$C$5:$C$36,$A44) -> 553 | D44: =SUMIFS('Raw Data'!$I$5:$I$36,'Raw Data'!$B$5:$B$36,"DUOL",'Raw Data'!$C$5:$C$36,$A44) -> 40.5 | E44: =IFERROR(C8/B44,"") -> 4.2055064 | G44: =IFERROR(D8/C44,"") -> 2.0870344 | H44: =IFERROR(E8/D44,"") -> 5.1740741
A45: Q1 2025 | B45: =SUMIFS('Raw Data'!$I$5:$I$36,'Raw Data'!$B$5:$B$36,"RDDT",'Raw Data'!$C$5:$C$36,$A45) -> 108.1 | C45: =SUMIFS('Raw Data'!$I$5:$I$36,'Raw Data'!$B$5:$B$36,"PINS",'Raw Data'!$C$5:$C$36,$A45) -> 570 | D45: =SUMIFS('Raw Data'!$I$5:$I$36,'Raw Data'!$B$5:$B$36,"DUOL",'Raw Data'!$C$5:$C$36,$A45) -> 46.6 | E45: =IFERROR(C9/B45,"") -> 3.6296115 | G45: =IFERROR(D9/C45,"") -> 1.4999789 | H45: =IFERROR(E9/D45,"") -> 4.9515665
A46: Q2 2025 | B46: =SUMIFS('Raw Data'!$I$5:$I$36,'Raw Data'!$B$5:$B$36,"RDDT",'Raw Data'!$C$5:$C$36,$A46) -> 110.4 | C46: =SUMIFS('Raw Data'!$I$5:$I$36,'Raw Data'!$B$5:$B$36,"PINS",'Raw Data'!$C$5:$C$36,$A46) -> 578 | D46: =SUMIFS('Raw Data'!$I$5:$I$36,'Raw Data'!$B$5:$B$36,"DUOL",'Raw Data'!$C$5:$C$36,$A46) -> 47.7 | E46: =IFERROR(C10/B46,"") -> 4.5256069 | G46: =IFERROR(D10/C46,"") -> 1.7270363 | H46: =IFERROR(E10/D46,"") -> 5.2885744
...

Sheet Pinterest Regions
A1: Pinterest revenue by region
A2: Geographic mix shows where growth is coming from. $ millions, as reported (rounded to $1M by the company).
A4: Quarter | B4: US & Canada | C4: Europe | D4: Rest of World | E4: Total | G4: Intl share | H4: Europe YoY | I4: RoW YoY
A5: Q3 2024 | B5: 719 | C5: 137 | D5: 42 | E5: =SUM(B5:D5) -> 898 | G5: =(C5+D5)/E5 -> 0.19933185
A6: Q4 2024 | B6: 900 | C6: 196 | D6: 58 | E6: =SUM(B6:D6) -> 1154 | G6: =(C6+D6)/E6 -> 0.22010399
A7: Q1 2025 | B7: 663 | C7: 147 | D7: 45 | E7: =SUM(B7:D7) -> 855 | G7: =(C7+D7)/E7 -> 0.2245614
A8: Q2 2025 | B8: 745 | C8: 191 | D8: 63 | E8: =SUM(B8:D8) -> 999 | G8: =(C8+D8)/E8 -> 0.25425425
A9: Q3 2025 | B9: 786 | C9: 193 | D9: 70 | E9: =SUM(B9:D9) -> 1049 | G9: =(C9+D9)/E9 -> 0.25071497 | H9: =IF(ROW()-ROW($A$5)>=4,C9/C5-1,"") -> 0.40875912 | I9: =IF(ROW()-ROW($A$5)>=4,D9/D5-1,"") -> 0.66666667
A10: Q4 2025 | B10: 979 | C10: 245 | D10: 96 | E10: =SUM(B10:D10) -> 1320 | G10: =(C10+D10)/E10 -> 0.25833333 | H10: =IF(ROW()-ROW($A$5)>=4,C10/C6-1,"") -> 0.25 | I10: =IF(ROW()-ROW($A$5)>=4,D10/D6-1,"") -> 0.65517241
A11: Q1 2026 | B11: 750 | C11: 186 | D11: 72 | E11: =SUM(B11:D11) -> 1008 | G11: =(C11+D11)/E11 -> 0.25595238 | H11: =IF(ROW()-ROW($A$5)>=4,C11/C7-1,"") -> 0.26530612 | I11: =IF(ROW()-ROW($A$5)>=4,D11/D7-1,"") -> 0.6
A12: Q2 2026 | B12: 880 | C12: 213 | D12: 87 | E12: =SUM(B12:D12) -> 1180 | G12: =(C12+D12)/E12 -> 0.25423729 | H12: =IF(ROW()-ROW($A$5)>=4,C12/C8-1,"") -> 0.11518325 | I12: =IF(ROW()-ROW($A$5)>=4,D12/D8-1,"") -> 0.38095238
A14: Check: regional total vs reported revenue
A15: Max gap ($M) | B15: =MAX(ABS(E5-SUMIFS('Raw Data'!$F$5:$F$36,'Raw Data'!$B$5:$B$36,"PINS",'Raw Data'!$C$5:$C$36,A5)),ABS(E6-SUMIFS('Raw Data'!$F$5:$F$36,'Raw Data'!$B$5:$B$36,"PINS",'Raw Data'!$C$5:$C$36,A6)),ABS(E7-SUMIFS('Raw Data'!$F$5:$F$36,'Raw Data'!$B$5:$B$36,"PINS",'Raw Data'!$C$5:$C$36,A7)),ABS(E8-SUMIFS('Raw Data'!$F$5:$F$36,'Raw Data'!$B$5:$B$36,"PINS",'Raw Data'!$C$5:$C$36,A8)),ABS(E9-SUMIFS('Raw Data'!$F$5:$F$36,'Raw Data'!$B$5:$B$36,"PINS",'Raw Data'!$C$5:$C$36,A9)),ABS(E10-SUMIFS('Raw Data'!$F$5:$F$36,'Raw Data'!$B$5:$B$36,"PINS",'Raw Data'!$C$5:$C$36,A10)),ABS(E11-SUMIFS('Raw Data'!$F$5:$F$36,'Raw Data'!$B$5:$B$36,"PINS",'Raw Data'!$C$5:$C$36,A11)),ABS(E12-SUMIFS('Raw Data'!$F$5:$F$36,'Raw Data'!$B$5:$B$36,"PINS",'Raw Data'!$C$5:$C$36,A12))) -> 0.773 | C15: Within company rounding (<$1.5M).

Sheet Sources
A1: Sources
A2: Each quarter's figures come from the release that first reported it or its year-later comparison column
A4: Key | B4: Document | C4: Link
A5: APP-3Q25 | B5: AppLovin Q3 2025 earnings release (8-K Ex. 99.1) | C5: https://www.sec.gov/Archives/edgar/data/1751008/000175100825000079/exhibit991-3q25earningspre.htm
A6: APP-4Q25 | B6: AppLovin Q4 2025 earnings release | C6: https://s21.q4cdn.com/165405286/files/doc_financials/2025/q4/v2/4Q25-AppLovin-Press-Release.pdf
A7: APP-1Q26 | B7: AppLovin Q1 2026 earnings release (8-K Ex. 99.1) | C7: https://www.sec.gov/Archives/edgar/data/0001751008/000175100826000042/exhibit991-1q26earningspre.htm
A8: APP-2Q26 | B8: AppLovin Q2 2026 earnings release (8-K Ex. 99.1) | C8: https://www.sec.gov/Archives/edgar/data/0001751008/000175100826000057/exhibit991-2q26earningspre.htm
A9: RDDT-3Q25 | B9: Reddit Q3 2025 earnings release (8-K) | C9: https://www.sec.gov/Archives/edgar/data/1713445/000171344525000225/earningspressreleaseq325.htm
A10: RDDT-4Q25 | B10: Reddit Q4 & FY2025 earnings release | C10: https://www.businesswire.com/news/home/20260205441801/en/Reddit-Reports-Fourth-Quarter-and-Full-Year-2025-Results-Announces-%241-Billion-Share-Repurchase-Program
A11: RDDT-1Q26 | B11: Reddit Q1 2026 earnings release (8-K) | C11: https://www.sec.gov/Archives/edgar/data/0001713445/000171344526000067/earningspressreleaseq126.htm
A12: RDDT-2Q26 | B12: Reddit Q2 2026 earnings release (8-K) | C12: https://www.sec.gov/Archives/edgar/data/0001713445/000171344526000098/earningspressreleaseq226.htm
A13: PINS-3Q25 | B13: Pinterest Q3 2025 earnings release (8-K) | C13: https://www.sec.gov/Archives/edgar/data/1506293/000150629325000228/q3-25xpressrelease.htm
A14: PINS-4Q25 | B14: Pinterest Q4 & FY2025 earnings release | C14: https://www.businesswire.com/news/home/20260212059914/en/Pinterest-Announces-Fourth-Quarter-and-Full-Year-2025-Results-Delivers-14-Revenue-Growth-and-Record-Users
A15: PINS-1Q26 | B15: Pinterest Q1 2026 earnings release (8-K) | C15: https://www.sec.gov/Archives/edgar/data/0001506293/000150629326000066/q1-26xpressrelease.htm
... A20: DUOL-2Q26 | B20: Duolingo Q2 2026 shareholder letter (8-K) | C20: https://www.sec.gov/Archives/edgar/data/0001562088/000162828026053299/q2fy26duolingo6-30x26share.htm
A23: Definitions
A24: Adj. EBITDA | B24: Company-defined non-GAAP measure; each company's reconciliation is in its release.
A25: DAUq | B25: Reddit daily active uniques: logged-in and logged-out users visiting at least once a day.
A26: MAU | B26: Pinterest monthly active users: authenticated users visiting at least once in the 30 days to period end.
A27: DAU | B27: Duolingo daily active users, averaged over the last month of the quarter.
A28: ARPU | B28: Average revenue per user as reported by the company for the quarter.
